Workbook

Sheet Dashboard
B1: Sales & Revenue Analysis Dashboard
B2: Jan 2025 - Sep 2026 | Use the yellow dropdowns to filter every KPI, chart and insight
B5: Year | C5: All | E5: Region | F5: All | H5: Category | I5: All | K5: Filters combine (e.g. 2026 + West + Software)
B7: TOTAL REVENUE | D7: TOTAL PROFIT | F7: PROFIT MARGIN | H7: ORDERS | J7: UNITS SOLD | L7: AVG ORDER VALUE
B8: =SUMIFS(Data!$K$2:$K$5000,Data!$C$2:$C$5000,Calc!$B$2,Data!$E$2:$E$5000,Calc!$B$3,Data!$F$2:$F$5000,Calc!$B$4) -> 32984077 | D8: =SUMIFS(Data!$L$2:$L$5000,Data!$C$2:$C$5000,Calc!$B$2,Data!$E$2:$E$5000,Calc!$B$3,Data!$F$2:$F$5000,Calc!$B$4) -> 13686917 | F8: =IFERROR((SUMIFS(Data!$L$2:$L$5000,Data!$C$2:$C$5000,Calc!$B$2,Data!$E$2:$E$5000,Calc!$B$3,Data!$F$2:$F$5000,Calc!$B$4))/(SUMIFS(Data!$K$2:$K$5000,Data!$C$2:$C$5000,Calc!$B$2,Data!$E$2:$E$5000,Calc!$B$3,Data!$F$2:$F$5000,Calc!$B$4)),0) -> 0.41495528 | H8: =COUNTIFS(Data!$C$2:$C$5000,Calc!$B$2,Data!$E$2:$E$5000,Calc!$B$3,Data!$F$2:$F$5000,Calc!$B$4) -> 650 | J8: =SUMIFS(Data!$H$2:$H$5000,Data!$C$2:$C$5000,Calc!$B$2,Data!$E$2:$E$5000,Calc!$B$3,Data!$F$2:$F$5000,Calc!$B$4) -> 10274 | L8: =IFERROR((SUMIFS(Data!$K$2:$K$5000,Data!$C$2:$C$5000,Calc!$B$2,Data!$E$2:$E$5000,Calc!$B$3,Data!$F$2:$F$5000,Calc!$B$4))/(COUNTIFS(Data!$C$2:$C$5000,Calc!$B$2,Data!$E$2:$E$5000,Calc!$B$3,Data!$F$2:$F$5000,Calc!$B$4)),0) -> 50744.734
B42: KEY BUSINESS INSIGHTS (update automatically with filters)
B43: ="Top product: "&Calc!B55&" with ₹"&TEXT(Calc!C55,"#,##0")&" revenue ("&TEXT(IFERROR(Calc!C55/(SUMIFS(Data!$K$2:$K$5000,Data!$C$2:$C$5000,Calc!$B$2,Data!$E$2:$E$5000,Calc!$B$3,Data!$F$2:$F$5000,Calc!$B$4)),0),"0.0%")&" of the total)." -> Top product: Laptop Pro 15 with ₹7,897,060 revenue (23.9% of the total).
B44: ="Best month: "&INDEX(Calc!A7:A18,MATCH(MAX(Calc!C7:C18),Calc!C7:C18,0))&" with ₹"&TEXT(MAX(Calc!C7:C18),"#,##0")&" revenue; weakest month: "&INDEX(Calc!A7:A18,MATCH(MIN(Calc!C7:C18),Calc!C7:C18,0))&" (₹"&TEXT(MIN(Calc!C7:C18),"#,##0")&")." -> Best month: Jul with ₹3,696,161 revenue; weakest month: Feb (₹1,748,429).
B45: ="Strongest region: "&INDEX(Calc!A22:A26,MATCH(MAX(Calc!B22:B26),Calc!B22:B26,0))&" (₹"&TEXT(MAX(Calc!B22:B26),"#,##0")&", "&TEXT(IFERROR(MAX(Calc!B22:B26)/SUM(Calc!B22:B26),0),"0.0%")&" share); weakest: "&INDEX(Calc!A22:A26,MATCH(MIN(Calc!B22:B26),Calc!B22:B26,0))&"." -> Strongest region: South (₹9,152,597, 27.7% share); weakest: Central.
B46: ="Largest category by revenue: "&INDEX(Calc!A31:A34,MATCH(MAX(Calc!B31:B34),Calc!B31:B34,0))&"; highest-margin category: "&INDEX(Calc!A31:A34,MATCH(MAX(Calc!D31:D34),Calc!D31:D34,0))&" ("&TEXT(MAX(Calc!D31:D34),"0.0%")&" margin)." -> Largest category by revenue: Electronics; highest-margin category: Software (67.0% margin).
B47: ="Top 5 products generate "&TEXT(IFERROR(SUM(Calc!C55:C59)/(SUMIFS(Data!$K$2:$K$5000,Data!$C$2:$C$5000,Calc!$B$2,Data!$E$2:$E$5000,Calc!$B$3,Data!$F$2:$F$5000,Calc!$B$4)),0),"0.0%")&" of revenue - a "&IF(IFERROR(SUM(Calc!C55:C59)/(SUMIFS(Data!$K$2:$K$5000,Data!$C$2:$C$5000,Calc!$B$2,Data!$E$2:$E$5000,Calc!$B$3,Data!$F$2:$F$5000,Calc!$B$4)),0)>0.7,"high concentration; diversify the product mix.","healthy spread across the catalogue.") -> Top 5 products generate 66.1% of revenue - a healthy spread across the catalogue.
B49: Sample data is synthetic. Replace the Data sheet with your own sales data and everything updates. See the Guide sheet.

Sheet Guide
B2: How to use this dashboard
B3: 1. Dashboard: pick Year / Region / Category from the yellow dropdowns; all KPIs, charts and insights recalculate.
B4: 2. Data: 650 sample sales transactions (synthetic). Replace columns A, B, E-J with your own data; copy formulas in C, D, K, L down.
B5: 3. Calc: helper tables that feed the charts. Do not edit.
B7: Importing your own data
B8: Excel: Data > Get Data > From Text/CSV (or From Workbook / From Database), then paste/load into the Data sheet.
B9: Google Sheets: File > Import > Upload your CSV/Excel, then copy it into the Data sheet columns.
B10: Database: export the query result as CSV and import as above, or use Power Query / Connected Sheets.
B12: Slicers
B13: Excel: click inside the Data table > Table Design > Insert Slicer to filter the raw data visually.
B14: Google Sheets: Data > Add a slicer. The Dashboard dropdowns work in both apps without any setup.
B16: KPI definitions
... B22: Formulas read Data rows 2-5000; extend the ranges in Calc/Dashboard if you exceed that.

Sheet Data
A1: Order ID | B1: Date | C1: Year | D1: Month | E1: Region | F1: Category | G1: Product | H1: Quantity | I1: Unit Price (₹) | J1: Unit Cost (₹) | K1: Revenue (₹) | L1: Profit (₹) | N1: Notes
A2: ORD-00001 | B2: 45658 | C2: =YEAR(B2) -> 2025 | D2: =MONTH(B2) -> 1 | E2: North | F2: Electronics | G2: Wireless Earbuds | H2: 9 | I2: 4240 | J2: 2800 | K2: =H2*I2 -> 38160 | L2: =H2*(I2-J2) -> 12960 | N2: Sample data is synthetic (seeded random) - replace rows A:J with your own sales data.
A3: ORD-00002 | B3: 45658 | C3: =YEAR(B3) -> 2025 | D3: =MONTH(B3) -> 1 | E3: South | F3: Electronics | G3: Laptop Pro 15 | H3: 3 | I3: 61950 | J3: 48000 | K3: =H3*I3 -> 185850 | L3: =H3*(I3-J3) -> 41850 | N3: Blue = hardcoded inputs; black = formulas (Year, Month, Revenue, Profit).
A4: ORD-00003 | B4: 45659 | C4: =YEAR(B4) -> 2025 | D4: =MONTH(B4) -> 1 | E4: North | F4: Electronics | G4: Laptop Pro 15 | H4: 3 | I4: 64130 | J4: 48000 | K4: =H4*I4 -> 192390 | L4: =H4*(I4-J4) -> 48390 | N4: To add rows: paste below the last row and copy the formulas in C, D, K, L down.
A5: ORD-00004 | B5: 45661 | C5: =YEAR(B5) -> 2025 | D5: =MONTH(B5) -> 1 | E5: South | F5: Electronics | G5: Laptop Pro 15 | H5: 3 | I5: 62870 | J5: 48000 | K5: =H5*I5 -> 188610 | L5: =H5*(I5-J5) -> 44610 | N5: Dashboard formulas read rows 2-5000 of this sheet.
A6: ORD-00005 | B6: 45663 | C6: =YEAR(B6) -> 2025 | D6: =MONTH(B6) -> 1 | E6: West | F6: Office Supplies | G6: Printer Paper Carton | H6: 12 | I6: 1830 | J6: 1250 | K6: =H6*I6 -> 21960 | L6: =H6*(I6-J6) -> 6960 | N6: Currency assumed to be Indian Rupees (₹) - change the number formats if needed.
A7: ORD-00006 | B7: 45663 | C7: =YEAR(B7) -> 2025 | D7: =MONTH(B7) -> 1 | E7: Central | F7: Furniture | G7: Standing Desk | H7: 3 | I7: 28690 | J7: 19500 | K7: =H7*I7 -> 86070 | L7: =H7*(I7-J7) -> 27570
A8: ORD-00007 | B8: 45664 | C8: =YEAR(B8) -> 2025 | D8: =MONTH(B8) -> 1 | E8: South | F8: Software | G8: Cloud Storage Plan | H8: 21 | I8: 4500 | J8: 1900 | K8: =H8*I8 -> 94500 | L8: =H8*(I8-J8) -> 54600
A9: ORD-00008 | B9: 45665 | C9: =YEAR(B9) -> 2025 | D9: =MONTH(B9) -> 1 | E9: North | F9: Software | G9: Cloud Storage Plan | H9: 8 | I9: 4790 | J9: 1900 | K9: =H9*I9 -> 38320 | L9: =H9*(I9-J9) -> 23120
A10: ORD-00009 | B10: 45667 | C10: =YEAR(B10) -> 2025 | D10: =MONTH(B10) -> 1 | E10: North | F10: Electronics | G10: Smart Monitor 27" | H10: 2 | I10: 19930 | J10: 15500 | K10: =H10*I10 -> 39860 | L10: =H10*(I10-J10) -> 8860
A11: ORD-00010 | B11: 45667 | C11: =YEAR(B11) -> 2025 | D11: =MONTH(B11) -> 1 | E11: North | F11: Electronics | G11: Laptop Pro 15 | H11: 2 | I11: 62360 | J11: 48000 | K11: =H11*I11 -> 124720 | L11: =H11*(I11-J11) -> 28720
A12: ORD-00011 | B12: 45669 | C12: =YEAR(B12) -> 2025 | D12: =MONTH(B12) -> 1 | E12: North | F12: Furniture | G12: Bookshelf | H12: 3 | I12: 7560 | J12: 4800 | K12: =H12*I12 -> 22680 | L12: =H12*(I12-J12) -> 8280
A13: ORD-00012 | B13: 45671 | C13: =YEAR(B13) -> 2025 | D13: =MONTH(B13) -> 1 | E13: South | F13: Office Supplies | G13: Gel Pen Box | H13: 39 | I13: 365 | J13: 170 | K13: =H13*I13 -> 14235 | L13: =H13*(I13-J13) -> 7605
A14: ORD-00013 | B14: 45676 | C14: =YEAR(B14) -> 2025 | D14: =MONTH(B14) -> 1 | E14: East | F14: Office Supplies | G14: Gel Pen Box | H14: 35 | I14: 347 | J14: 170 | K14: =H14*I14 -> 12145 | L14: =H14*(I14-J14) -> 6195
A15: ORD-00014 | B15: 45676 | C15: =YEAR(B15) -> 2025 | D15: =MONTH(B15) -> 1 | E15: West | F15: Office Supplies | G15: Premium Notebook Set | H15: 27 | I15: 671 | J15: 320 | K15: =H15*I15 -> 18117 | L15: =H15*(I15-J15) -> 9477
A16: ORD-00015 | B16: 45677 | C16: =YEAR(B16) -> 2025 | D16: =MONTH(B16) -> 1 | E16: North | F16: Electronics | G16: Laptop Pro 15 | H16: 2 | I16: 61720 | J16: 48000 | K16: =H16*I16 -> 123440 | L16: =H16*(I16-J16) -> 27440
A17: ORD-00016 | B17: 45680 | C17: =YEAR(B17) -> 2025 | D17: =MONTH(B17) -> 1 | E17: Central | F17: Software | G17: Productivity Suite License | H17: 15 | I17: 8960 | J17: 2500 | K17: =H17*I17 -> 134400 | L17: =H17*(I17-J17) -> 96900
A18: ORD-00017 | B18: 45681 | C18: =YEAR(B18) -> 2025 | D18: =MONTH(B18) -> 1 | E18: West | F18: Office Supplies | G18: Printer Paper Carton | H18: 13 | I18: 1770 | J18: 1250 | K18: =H18*I18 -> 23010 | L18: =H18*(I18-J18) -> 6760
... A651: ORD-00650 | B651: 46295 | C651: =YEAR(B651) -> 2026 | D651: =MONTH(B651) -> 9 | E651: South | F651: Electronics | G651: Smart Monitor 27" | H651: 4 | I651: 21620 | J651: 15500 | K651: =H651*I651 -> 86480 | L651: =H651*(I651-J651) -> 24480

Sheet Calc
A1: Calculation sheet (feeds Dashboard charts - do not edit)
A2: Year criteria | B2: =IF(Dashboard!$C$5="All","<>",Dashboard!$C$5) -> <>
A3: Region criteria | B3: =IF(Dashboard!$F$5="All","<>",Dashboard!$F$5) -> <>
A4: Category criteria | B4: =IF(Dashboard!$I$5="All","<>",Dashboard!$I$5) -> <>
A5: Monthly trend
A6: Month | B6: Month # | C6: Revenue | D6: Profit
A7: Jan | B7: 1 | C7: =SUMIFS(Data!$K$2:$K$5000,Data!$D$2:$D$5000,$B7,Data!$C$2:$C$5000,Calc!$B$2,Data!$E$2:$E$5000,Calc!$B$3,Data!$F$2:$F$5000,Calc!$B$4) -> 3001373 | D7: =SUMIFS(Data!$L$2:$L$5000,Data!$D$2:$D$5000,$B7,Data!$C$2:$C$5000,Calc!$B$2,Data!$E$2:$E$5000,Calc!$B$3,Data!$F$2:$F$5000,Calc!$B$4) -> 1133553
A8: Feb | B8: 2 | C8: =SUMIFS(Data!$K$2:$K$5000,Data!$D$2:$D$5000,$B8,Data!$C$2:$C$5000,Calc!$B$2,Data!$E$2:$E$5000,Calc!$B$3,Data!$F$2:$F$5000,Calc!$B$4) -> 1748429 | D8: =SUMIFS(Data!$L$2:$L$5000,Data!$D$2:$D$5000,$B8,Data!$C$2:$C$5000,Calc!$B$2,Data!$E$2:$E$5000,Calc!$B$3,Data!$F$2:$F$5000,Calc!$B$4) -> 753589
A9: Mar | B9: 3 | C9: =SUMIFS(Data!$K$2:$K$5000,Data!$D$2:$D$5000,$B9,Data!$C$2:$C$5000,Calc!$B$2,Data!$E$2:$E$5000,Calc!$B$3,Data!$F$2:$F$5000,Calc!$B$4) -> 3328061 | D9: =SUMIFS(Data!$L$2:$L$5000,Data!$D$2:$D$5000,$B9,Data!$C$2:$C$5000,Calc!$B$2,Data!$E$2:$E$5000,Calc!$B$3,Data!$F$2:$F$5000,Calc!$B$4) -> 1340441
A10: Apr | B10: 4 | C10: =SUMIFS(Data!$K$2:$K$5000,Data!$D$2:$D$5000,$B10,Data!$C$2:$C$5000,Calc!$B$2,Data!$E$2:$E$5000,Calc!$B$3,Data!$F$2:$F$5000,Calc!$B$4) -> 3307596 | D10: =SUMIFS(Data!$L$2:$L$5000,Data!$D$2:$D$5000,$B10,Data!$C$2:$C$5000,Calc!$B$2,Data!$E$2:$E$5000,Calc!$B$3,Data!$F$2:$F$5000,Calc!$B$4) -> 1327276
A11: May | B11: 5 | C11: =SUMIFS(Data!$K$2:$K$5000,Data!$D$2:$D$5000,$B11,Data!$C$2:$C$5000,Calc!$B$2,Data!$E$2:$E$5000,Calc!$B$3,Data!$F$2:$F$5000,Calc!$B$4) -> 2496977 | D11: =SUMIFS(Data!$L$2:$L$5000,Data!$D$2:$D$5000,$B11,Data!$C$2:$C$5000,Calc!$B$2,Data!$E$2:$E$5000,Calc!$B$3,Data!$F$2:$F$5000,Calc!$B$4) -> 1190357
A12: Jun | B12: 6 | C12: =SUMIFS(Data!$K$2:$K$5000,Data!$D$2:$D$5000,$B12,Data!$C$2:$C$5000,Calc!$B$2,Data!$E$2:$E$5000,Calc!$B$3,Data!$F$2:$F$5000,Calc!$B$4) -> 2704399 | D12: =SUMIFS(Data!$L$2:$L$5000,Data!$D$2:$D$5000,$B12,Data!$C$2:$C$5000,Calc!$B$2,Data!$E$2:$E$5000,Calc!$B$3,Data!$F$2:$F$5000,Calc!$B$4) -> 1124079
A13: Jul | B13: 7 | C13: =SUMIFS(Data!$K$2:$K$5000,Data!$D$2:$D$5000,$B13,Data!$C$2:$C$5000,Calc!$B$2,Data!$E$2:$E$5000,Calc!$B$3,Data!$F$2:$F$5000,Calc!$B$4) -> 3696161 | D13: =SUMIFS(Data!$L$2:$L$5000,Data!$D$2:$D$5000,$B13,Data!$C$2:$C$5000,Calc!$B$2,Data!$E$2:$E$5000,Calc!$B$3,Data!$F$2:$F$5000,Calc!$B$4) -> 1527611
A14: Aug | B14: 8 | C14: =SUMIFS(Data!$K$2:$K$5000,Data!$D$2:$D$5000,$B14,Data!$C$2:$C$5000,Calc!$B$2,Data!$E$2:$E$5000,Calc!$B$3,Data!$F$2:$F$5000,Calc!$B$4) -> 3418523 | D14: =SUMIFS(Data!$L$2:$L$5000,Data!$D$2:$D$5000,$B14,Data!$C$2:$C$5000,Calc!$B$2,Data!$E$2:$E$5000,Calc!$B$3,Data!$F$2:$F$5000,Calc!$B$4) -> 1483183
A15: Sep | B15: 9 | C15: =SUMIFS(Data!$K$2:$K$5000,Data!$D$2:$D$5000,$B15,Data!$C$2:$C$5000,Calc!$B$2,Data!$E$2:$E$5000,Calc!$B$3,Data!$F$2:$F$5000,Calc!$B$4) -> 3387651 | D15: =SUMIFS(Data!$L$2:$L$5000,Data!$D$2:$D$5000,$B15,Data!$C$2:$C$5000,Calc!$B$2,Data!$E$2:$E$5000,Calc!$B$3,Data!$F$2:$F$5000,Calc!$B$4) -> 1352311
A16: Oct | B16: 10 | C16: =SUMIFS(Data!$K$2:$K$5000,Data!$D$2:$D$5000,$B16,Data!$C$2:$C$5000,Calc!$B$2,Data!$E$2:$E$5000,Calc!$B$3,Data!$F$2:$F$5000,Calc!$B$4) -> 1778743 | D16: =SUMIFS(Data!$L$2:$L$5000,Data!$D$2:$D$5000,$B16,Data!$C$2:$C$5000,Calc!$B$2,Data!$E$2:$E$5000,Calc!$B$3,Data!$F$2:$F$5000,Calc!$B$4) -> 683363
A17: Nov | B17: 11 | C17: =SUMIFS(Data!$K$2:$K$5000,Data!$D$2:$D$5000,$B17,Data!$C$2:$C$5000,Calc!$B$2,Data!$E$2:$E$5000,Calc!$B$3,Data!$F$2:$F$5000,Calc!$B$4) -> 1909288 | D17: =SUMIFS(Data!$L$2:$L$5000,Data!$D$2:$D$5000,$B17,Data!$C$2:$C$5000,Calc!$B$2,Data!$E$2:$E$5000,Calc!$B$3,Data!$F$2:$F$5000,Calc!$B$4) -> 866068
A18: Dec | B18: 12 | C18: =SUMIFS(Data!$K$2:$K$5000,Data!$D$2:$D$5000,$B18,Data!$C$2:$C$5000,Calc!$B$2,Data!$E$2:$E$5000,Calc!$B$3,Data!$F$2:$F$5000,Calc!$B$4) -> 2206876 | D18: =SUMIFS(Data!$L$2:$L$5000,Data!$D$2:$D$5000,$B18,Data!$C$2:$C$5000,Calc!$B$2,Data!$E$2:$E$5000,Calc!$B$3,Data!$F$2:$F$5000,Calc!$B$4) -> 905086
A20: Revenue by region
A21: Region | B21: Revenue
A22: North | B22: =SUMIFS(Data!$K$2:$K$5000,Data!$E$2:$E$5000,$A22,Data!$C$2:$C$5000,$B$2,Data!$F$2:$F$5000,$B$4) -> 6365822
A23: South | B23: =SUMIFS(Data!$K$2:$K$5000,Data!$E$2:$E$5000,$A23,Data!$C$2:$C$5000,$B$2,Data!$F$2:$F$5000,$B$4) -> 9152597
A24: East | B24: =SUMIFS(Data!$K$2:$K$5000,Data!$E$2:$E$5000,$A24,Data!$C$2:$C$5000,$B$2,Data!$F$2:$F$5000,$B$4) -> 5176718
A25: West | B25: =SUMIFS(Data!$K$2:$K$5000,Data!$E$2:$E$5000,$A25,Data!$C$2:$C$5000,$B$2,Data!$F$2:$F$5000,$B$4) -> 7270578
A26: Central | B26: =SUMIFS(Data!$K$2:$K$5000,Data!$E$2:$E$5000,$A26,Data!$C$2:$C$5000,$B$2,Data!$F$2:$F$5000,$B$4) -> 5018362
A29: Revenue by category
A30: Category | B30: Revenue | C30: Profit | D30: Margin
A31: Electronics | B31: =SUMIFS(Data!$K$2:$K$5000,Data!$F$2:$F$5000,$A31,Data!$C$2:$C$5000,$B$2,Data!$E$2:$E$5000,$B$3) -> 12949330 | C31: =SUMIFS(Data!$L$2:$L$5000,Data!$F$2:$F$5000,$A31,Data!$C$2:$C$5000,$B$2,Data!$E$2:$E$5000,$B$3) -> 3272030 | D31: =IFERROR(C31/B31,0) -> 0.25267948
A32: Furniture | B32: =SUMIFS(Data!$K$2:$K$5000,Data!$F$2:$F$5000,$A32,Data!$C$2:$C$5000,$B$2,Data!$E$2:$E$5000,$B$3) -> 5495670 | C32: =SUMIFS(Data!$L$2:$L$5000,Data!$F$2:$F$5000,$A32,Data!$C$2:$C$5000,$B$2,Data!$E$2:$E$5000,$B$3) -> 1795170 | D32: =IFERROR(C32/B32,0) -> 0.32665171
A33: Office Supplies | B33: =SUMIFS(Data!$K$2:$K$5000,Data!$F$2:$F$5000,$A33,Data!$C$2:$C$5000,$B$2,Data!$E$2:$E$5000,$B$3) -> 4619417 | C33: =SUMIFS(Data!$L$2:$L$5000,Data!$F$2:$F$5000,$A33,Data!$C$2:$C$5000,$B$2,Data!$E$2:$E$5000,$B$3) -> 1976257 | D33: =IFERROR(C33/B33,0) -> 0.42781524
A34: Software | B34: =SUMIFS(Data!$K$2:$K$5000,Data!$F$2:$F$5000,$A34,Data!$C$2:$C$5000,$B$2,Data!$E$2:$E$5000,$B$3) -> 9919660 | C34: =SUMIFS(Data!$L$2:$L$5000,Data!$F$2:$F$5000,$A34,Data!$C$2:$C$5000,$B$2,Data!$E$2:$E$5000,$B$3) -> 6643460 | D34: =IFERROR(C34/B34,0) -> 0.66972658
A37: Revenue by product
A38: Product | B38: Category | C38: Revenue | D38: Units | E38: Rank key
A39: Laptop Pro 15 | B39: Electronics | C39: =SUMIFS(Data!$K$2:$K$5000,Data!$G$2:$G$5000,$A39,Data!$C$2:$C$5000,Calc!$B$2,Data!$E$2:$E$5000,Calc!$B$3,Data!$F$2:$F$5000,Calc!$B$4) -> 7897060 | D39: =SUMIFS(Data!$H$2:$H$5000,Data!$G$2:$G$5000,$A39,Data!$C$2:$C$5000,Calc!$B$2,Data!$E$2:$E$5000,Calc!$B$3,Data!$F$2:$F$5000,Calc!$B$4) -> 129 | E39: =C39+ROW()/1000000 -> 7897060
A40: Wireless Earbuds | B40: Electronics | C40: =SUMIFS(Data!$K$2:$K$5000,Data!$G$2:$G$5000,$A40,Data!$C$2:$C$5000,Calc!$B$2,Data!$E$2:$E$5000,Calc!$B$3,Data!$F$2:$F$5000,Calc!$B$4) -> 2602870 | D40: =SUMIFS(Data!$H$2:$H$5000,Data!$G$2:$G$5000,$A40,Data!$C$2:$C$5000,Calc!$B$2,Data!$E$2:$E$5000,Calc!$B$3,Data!$F$2:$F$5000,Calc!$B$4) -> 586 | E40: =C40+ROW()/1000000 -> 2602870
A41: Smart Monitor 27" | B41: Electronics | C41: =SUMIFS(Data!$K$2:$K$5000,Data!$G$2:$G$5000,$A41,Data!$C$2:$C$5000,Calc!$B$2,Data!$E$2:$E$5000,Calc!$B$3,Data!$F$2:$F$5000,Calc!$B$4) -> 2449400 | D41: =SUMIFS(Data!$H$2:$H$5000,Data!$G$2:$G$5000,$A41,Data!$C$2:$C$5000,Calc!$B$2,Data!$E$2:$E$5000,Calc!$B$3,Data!$F$2:$F$5000,Calc!$B$4) -> 119 | E41: =C41+ROW()/1000000 -> 2449400
A42: Ergonomic Chair | B42: Furniture | C42: =SUMIFS(Data!$K$2:$K$5000,Data!$G$2:$G$5000,$A42,Data!$C$2:$C$5000,Calc!$B$2,Data!$E$2:$E$5000,Calc!$B$3,Data!$F$2:$F$5000,Calc!$B$4) -> 2466650 | D42: =SUMIFS(Data!$H$2:$H$5000,Data!$G$2:$G$5000,$A42,Data!$C$2:$C$5000,Calc!$B$2,Data!$E$2:$E$5000,Calc!$B$3,Data!$F$2:$F$5000,Calc!$B$4) -> 179 | E42: =C42+ROW()/1000000 -> 2466650
A43: Standing Desk | B43: Furniture | C43: =SUMIFS(Data!$K$2:$K$5000,Data!$G$2:$G$5000,$A43,Data!$C$2:$C$5000,Calc!$B$2,Data!$E$2:$E$5000,Calc!$B$3,Data!$F$2:$F$5000,Calc!$B$4) -> 2364140 | D43: =SUMIFS(Data!$H$2:$H$5000,Data!$G$2:$G$5000,$A43,Data!$C$2:$C$5000,Calc!$B$2,Data!$E$2:$E$5000,Calc!$B$3,Data!$F$2:$F$5000,Calc!$B$4) -> 85 | E43: =C43+ROW()/1000000 -> 2364140
A44: Bookshelf | B44: Furniture | C44: =SUMIFS(Data!$K$2:$K$5000,Data!$G$2:$G$5000,$A44,Data!$C$2:$C$5000,Calc!$B$2,Data!$E$2:$E$5000,Calc!$B$3,Data!$F$2:$F$5000,Calc!$B$4) -> 664880 | D44: =SUMIFS(Data!$H$2:$H$5000,Data!$G$2:$G$5000,$A44,Data!$C$2:$C$5000,Calc!$B$2,Data!$E$2:$E$5000,Calc!$B$3,Data!$F$2:$F$5000,Calc!$B$4) -> 90 | E44: =C44+ROW()/1000000 -> 664880
A45: Premium Notebook Set | B45: Office Supplies | C45: =SUMIFS(Data!$K$2:$K$5000,Data!$G$2:$G$5000,$A45,Data!$C$2:$C$5000,Calc!$B$2,Data!$E$2:$E$5000,Calc!$B$3,Data!$F$2:$F$5000,Calc!$B$4) -> 1570991 | D45: =SUMIFS(Data!$H$2:$H$5000,Data!$G$2:$G$5000,$A45,Data!$C$2:$C$5000,Calc!$B$2,Data!$E$2:$E$5000,Calc!$B$3,Data!$F$2:$F$5000,Calc!$B$4) -> 2408 | E45: =C45+ROW()/1000000 -> 1570991
...
